[2024-09-03T08:12:44.291+0000] {taskinstance.py:1157} INFO - Dependencies all met for dep_context=non-requeueable deps ti=<TaskInstance: k9_etl_dag_v2.create_k9_table manual__2024-09-03T08:12:43.148280+00:00 [queued]>
[2024-09-03T08:12:44.297+0000] {taskinstance.py:1157} INFO - Dependencies all met for dep_context=requeueable deps ti=<TaskInstance: k9_etl_dag_v2.create_k9_table manual__2024-09-03T08:12:43.148280+00:00 [queued]>
[2024-09-03T08:12:44.297+0000] {taskinstance.py:1359} INFO - Starting attempt 1 of 1
[2024-09-03T08:12:44.304+0000] {taskinstance.py:1380} INFO - Executing <Task(SQLExecuteQueryOperator): create_k9_table> on 2024-09-03 08:12:43.148280+00:00
[2024-09-03T08:12:44.309+0000] {standard_task_runner.py:57} INFO - Started process 172 to run task
[2024-09-03T08:12:44.312+0000] {standard_task_runner.py:84} INFO - Running: ['***', 'tasks', 'run', 'k9_etl_dag_v2', 'create_k9_table', 'manual__2024-09-03T08:12:43.148280+00:00', '--job-id', '5', '--raw', '--subdir', 'DAGS_FOLDER/k9_etl_dag_v2.py', '--cfg-path', '/tmp/tmp23ayb64o']
[2024-09-03T08:12:44.313+0000] {standard_task_runner.py:85} INFO - Job 5: Subtask create_k9_table
[2024-09-03T08:12:44.386+0000] {task_command.py:415} INFO - Running <TaskInstance: k9_etl_dag_v2.create_k9_table manual__2024-09-03T08:12:43.148280+00:00 [running]> on host 52afa4428dd5
[2024-09-03T08:12:44.473+0000] {taskinstance.py:1660} INFO - Exporting env vars: AIRFLOW_CTX_DAG_OWNER='***' AIRFLOW_CTX_DAG_ID='k9_etl_dag_v2' AIRFLOW_CTX_TASK_ID='create_k9_table' AIRFLOW_CTX_EXECUTION_DATE='2024-09-03T08:12:43.148280+00:00' AIRFLOW_CTX_TRY_NUMBER='1' AIRFLOW_CTX_DAG_RUN_ID='manual__2024-09-03T08:12:43.148280+00:00'
[2024-09-03T08:12:44.473+0000] {sql.py:274} INFO - Executing: 
        CREATE TABLE IF NOT EXISTS k9_facts_v2 (
            id SERIAL PRIMARY KEY,
            fact_id INTEGER,
            created_date TIMESTAMP,
            description TEXT,
            category VARCHAR(50),
            version INTEGER,
            is_current BOOLEAN
        );
        
[2024-09-03T08:12:44.482+0000] {base.py:73} INFO - Using connection ID 'k9_care' for task execution.
[2024-09-03T08:12:44.508+0000] {base.py:73} INFO - Using connection ID 'k9_care' for task execution.
[2024-09-03T08:12:44.511+0000] {taskinstance.py:1935} ERROR - Task failed with exception
Traceback (most recent call last):
  File "/home/airflow/.local/lib/python3.8/site-packages/airflow/providers/common/sql/operators/sql.py", line 280, in execute
    output = hook.run(
  File "/home/airflow/.local/lib/python3.8/site-packages/airflow/providers/common/sql/hooks/sql.py", line 385, in run
    with closing(self.get_conn()) as conn:
  File "/home/airflow/.local/lib/python3.8/site-packages/airflow/providers/postgres/hooks/postgres.py", line 154, in get_conn
    self.conn = psycopg2.connect(**conn_args)
  File "/home/airflow/.local/lib/python3.8/site-packages/psycopg2/__init__.py", line 122, in connect
    conn = _connect(dsn, connection_factory=connection_factory, **kwasync)
psycopg2.OperationalError: could not connect to server: Connection refused
	Is the server running on host "127.0.0.1" and accepting
	TCP/IP connections on port 5432?

[2024-09-03T08:12:44.521+0000] {taskinstance.py:1398} INFO - Marking task as FAILED. dag_id=k9_etl_dag_v2, task_id=create_k9_table, execution_date=20240903T081243, start_date=20240903T081244, end_date=20240903T081244
[2024-09-03T08:12:44.527+0000] {standard_task_runner.py:104} ERROR - Failed to execute job 5 for task create_k9_table (could not connect to server: Connection refused
	Is the server running on host "127.0.0.1" and accepting
	TCP/IP connections on port 5432?
; 172)
[2024-09-03T08:12:44.538+0000] {local_task_job_runner.py:228} INFO - Task exited with return code 1
[2024-09-03T08:12:44.553+0000] {taskinstance.py:2776} INFO - 0 downstream tasks scheduled from follow-on schedule check
