[2024-09-02T19:13:34.816+0000] {taskinstance.py:1157} INFO - Dependencies all met for dep_context=non-requeueable deps ti=<TaskInstance: k9_etl_dag.create_k9_table manual__2024-09-02T19:13:33.849492+00:00 [queued]>
[2024-09-02T19:13:34.821+0000] {taskinstance.py:1157} INFO - Dependencies all met for dep_context=requeueable deps ti=<TaskInstance: k9_etl_dag.create_k9_table manual__2024-09-02T19:13:33.849492+00:00 [queued]>
[2024-09-02T19:13:34.821+0000] {taskinstance.py:1359} INFO - Starting attempt 1 of 1
[2024-09-02T19:13:34.828+0000] {taskinstance.py:1380} INFO - Executing <Task(SQLExecuteQueryOperator): create_k9_table> on 2024-09-02 19:13:33.849492+00:00
[2024-09-02T19:13:34.833+0000] {standard_task_runner.py:57} INFO - Started process 284 to run task
[2024-09-02T19:13:34.837+0000] {standard_task_runner.py:84} INFO - Running: ['***', 'tasks', 'run', 'k9_etl_dag', 'create_k9_table', 'manual__2024-09-02T19:13:33.849492+00:00', '--job-id', '14', '--raw', '--subdir', 'DAGS_FOLDER/k9_etl_dag.py', '--cfg-path', '/tmp/tmp1_sh1c71']
[2024-09-02T19:13:34.839+0000] {standard_task_runner.py:85} INFO - Job 14: Subtask create_k9_table
[2024-09-02T19:13:34.924+0000] {task_command.py:415} INFO - Running <TaskInstance: k9_etl_dag.create_k9_table manual__2024-09-02T19:13:33.849492+00:00 [running]> on host 6b66813f7393
[2024-09-02T19:13:35.050+0000] {taskinstance.py:1660} INFO - Exporting env vars: AIRFLOW_CTX_DAG_OWNER='***' AIRFLOW_CTX_DAG_ID='k9_etl_dag' AIRFLOW_CTX_TASK_ID='create_k9_table' AIRFLOW_CTX_EXECUTION_DATE='2024-09-02T19:13:33.849492+00:00' AIRFLOW_CTX_TRY_NUMBER='1' AIRFLOW_CTX_DAG_RUN_ID='manual__2024-09-02T19:13:33.849492+00:00'
[2024-09-02T19:13:35.051+0000] {sql.py:274} INFO - Executing: 
        CREATE TABLE IF NOT EXISTS k9_facts (
            id SERIAL PRIMARY KEY,
            created_date TIMESTAMP,
            description TEXT
        );
        
[2024-09-02T19:13:35.061+0000] {base.py:73} INFO - Using connection ID 'k9_care' for task execution.
[2024-09-02T19:13:35.078+0000] {base.py:73} INFO - Using connection ID 'k9_care' for task execution.
[2024-09-02T19:13:35.084+0000] {taskinstance.py:1935} ERROR - Task failed with exception
Traceback (most recent call last):
  File "/home/airflow/.local/lib/python3.8/site-packages/airflow/providers/common/sql/operators/sql.py", line 280, in execute
    output = hook.run(
  File "/home/airflow/.local/lib/python3.8/site-packages/airflow/providers/common/sql/hooks/sql.py", line 385, in run
    with closing(self.get_conn()) as conn:
  File "/home/airflow/.local/lib/python3.8/site-packages/airflow/providers/postgres/hooks/postgres.py", line 154, in get_conn
    self.conn = psycopg2.connect(**conn_args)
  File "/home/airflow/.local/lib/python3.8/site-packages/psycopg2/__init__.py", line 121, in connect
    dsn = _ext.make_dsn(dsn, **kwargs)
  File "/home/airflow/.local/lib/python3.8/site-packages/psycopg2/extensions.py", line 167, in make_dsn
    parse_dsn(dsn)
psycopg2.ProgrammingError: invalid dsn: invalid connection option "this_param"

[2024-09-02T19:13:35.097+0000] {taskinstance.py:1398} INFO - Marking task as FAILED. dag_id=k9_etl_dag, task_id=create_k9_table, execution_date=20240902T191333, start_date=20240902T191334, end_date=20240902T191335
[2024-09-02T19:13:35.106+0000] {standard_task_runner.py:104} ERROR - Failed to execute job 14 for task create_k9_table (invalid dsn: invalid connection option "this_param"
; 284)
[2024-09-02T19:13:35.139+0000] {local_task_job_runner.py:228} INFO - Task exited with return code 1
[2024-09-02T19:13:35.157+0000] {taskinstance.py:2776} INFO - 0 downstream tasks scheduled from follow-on schedule check
