[2024-09-03T08:10:57.945+0000] {taskinstance.py:1157} INFO - Dependencies all met for dep_context=non-requeueable deps ti=<TaskInstance: k9_etl_dag_v2.create_k9_table manual__2024-09-03T08:10:55.925786+00:00 [queued]>
[2024-09-03T08:10:57.953+0000] {taskinstance.py:1157} INFO - Dependencies all met for dep_context=requeueable deps ti=<TaskInstance: k9_etl_dag_v2.create_k9_table manual__2024-09-03T08:10:55.925786+00:00 [queued]>
[2024-09-03T08:10:57.955+0000] {taskinstance.py:1359} INFO - Starting attempt 1 of 1
[2024-09-03T08:10:57.986+0000] {taskinstance.py:1380} INFO - Executing <Task(SQLExecuteQueryOperator): create_k9_table> on 2024-09-03 08:10:55.925786+00:00
[2024-09-03T08:10:57.995+0000] {standard_task_runner.py:57} INFO - Started process 145 to run task
[2024-09-03T08:10:58.010+0000] {standard_task_runner.py:84} INFO - Running: ['***', 'tasks', 'run', 'k9_etl_dag_v2', 'create_k9_table', 'manual__2024-09-03T08:10:55.925786+00:00', '--job-id', '3', '--raw', '--subdir', 'DAGS_FOLDER/k9_etl_dag_v2.py', '--cfg-path', '/tmp/tmpc66eapl_']
[2024-09-03T08:10:58.014+0000] {standard_task_runner.py:85} INFO - Job 3: Subtask create_k9_table
[2024-09-03T08:10:58.055+0000] {task_command.py:415} INFO - Running <TaskInstance: k9_etl_dag_v2.create_k9_table manual__2024-09-03T08:10:55.925786+00:00 [running]> on host 52afa4428dd5
[2024-09-03T08:10:58.104+0000] {taskinstance.py:1660} INFO - Exporting env vars: AIRFLOW_CTX_DAG_OWNER='***' AIRFLOW_CTX_DAG_ID='k9_etl_dag_v2' AIRFLOW_CTX_TASK_ID='create_k9_table' AIRFLOW_CTX_EXECUTION_DATE='2024-09-03T08:10:55.925786+00:00' AIRFLOW_CTX_TRY_NUMBER='1' AIRFLOW_CTX_DAG_RUN_ID='manual__2024-09-03T08:10:55.925786+00:00'
[2024-09-03T08:10:58.106+0000] {sql.py:274} INFO - Executing: 
        CREATE TABLE IF NOT EXISTS k9_facts_v2 (
            id SERIAL PRIMARY KEY,
            fact_id INTEGER,
            created_date TIMESTAMP,
            description TEXT,
            category VARCHAR(50),
            version INTEGER,
            is_current BOOLEAN
        );
        
[2024-09-03T08:10:58.119+0000] {taskinstance.py:1935} ERROR - Task failed with exception
Traceback (most recent call last):
  File "/home/airflow/.local/lib/python3.8/site-packages/airflow/providers/common/sql/operators/sql.py", line 275, in execute
    hook = self.get_db_hook()
  File "/home/airflow/.local/lib/python3.8/site-packages/airflow/providers/common/sql/operators/sql.py", line 186, in get_db_hook
    return self._hook
  File "/usr/local/lib/python3.8/functools.py", line 967, in __get__
    val = self.func(instance)
  File "/home/airflow/.local/lib/python3.8/site-packages/airflow/providers/common/sql/operators/sql.py", line 148, in _hook
    conn = BaseHook.get_connection(conn_id)
  File "/home/airflow/.local/lib/python3.8/site-packages/airflow/hooks/base.py", line 72, in get_connection
    conn = Connection.get_connection_from_secrets(conn_id)
  File "/home/airflow/.local/lib/python3.8/site-packages/airflow/models/connection.py", line 477, in get_connection_from_secrets
    raise AirflowNotFoundException(f"The conn_id `{conn_id}` isn't defined")
airflow.exceptions.AirflowNotFoundException: The conn_id `k9_care` isn't defined
[2024-09-03T08:10:58.124+0000] {taskinstance.py:1398} INFO - Marking task as FAILED. dag_id=k9_etl_dag_v2, task_id=create_k9_table, execution_date=20240903T081055, start_date=20240903T081057, end_date=20240903T081058
[2024-09-03T08:10:58.132+0000] {standard_task_runner.py:104} ERROR - Failed to execute job 3 for task create_k9_table (The conn_id `k9_care` isn't defined; 145)
[2024-09-03T08:10:58.141+0000] {local_task_job_runner.py:228} INFO - Task exited with return code 1
[2024-09-03T08:10:58.157+0000] {taskinstance.py:2776} INFO - 0 downstream tasks scheduled from follow-on schedule check
