[2024-09-03T14:46:24.700+0000] {taskinstance.py:1157} INFO - Dependencies all met for dep_context=non-requeueable deps ti=<TaskInstance: k9_etl_dag_v7.send_report_email scheduled__2024-09-02T00:00:00+00:00 [queued]>
[2024-09-03T14:46:24.710+0000] {taskinstance.py:1157} INFO - Dependencies all met for dep_context=requeueable deps ti=<TaskInstance: k9_etl_dag_v7.send_report_email scheduled__2024-09-02T00:00:00+00:00 [queued]>
[2024-09-03T14:46:24.711+0000] {taskinstance.py:1359} INFO - Starting attempt 1 of 2
[2024-09-03T14:46:24.723+0000] {taskinstance.py:1380} INFO - Executing <Task(EmailOperator): send_report_email> on 2024-09-02 00:00:00+00:00
[2024-09-03T14:46:24.736+0000] {standard_task_runner.py:57} INFO - Started process 2913 to run task
[2024-09-03T14:46:24.743+0000] {standard_task_runner.py:84} INFO - Running: ['***', 'tasks', 'run', 'k9_etl_dag_v7', 'send_report_email', 'scheduled__2024-09-02T00:00:00+00:00', '--job-id', '126', '--raw', '--subdir', 'DAGS_FOLDER/k9_etl_dag_v7.py', '--cfg-path', '/tmp/tmprh3bbhbn']
[2024-09-03T14:46:24.749+0000] {standard_task_runner.py:85} INFO - Job 126: Subtask send_report_email
[2024-09-03T14:46:24.848+0000] {task_command.py:415} INFO - Running <TaskInstance: k9_etl_dag_v7.send_report_email scheduled__2024-09-02T00:00:00+00:00 [running]> on host 2624bebdd8ee
[2024-09-03T14:46:24.940+0000] {taskinstance.py:1660} INFO - Exporting env vars: AIRFLOW_CTX_DAG_EMAIL='your-email@example.com' AIRFLOW_CTX_DAG_OWNER='***' AIRFLOW_CTX_DAG_ID='k9_etl_dag_v7' AIRFLOW_CTX_TASK_ID='send_report_email' AIRFLOW_CTX_EXECUTION_DATE='2024-09-02T00:00:00+00:00' AIRFLOW_CTX_TRY_NUMBER='1' AIRFLOW_CTX_DAG_RUN_ID='scheduled__2024-09-02T00:00:00+00:00'
[2024-09-03T14:46:24.954+0000] {warnings.py:109} WARNING - /home/***/.local/lib/python3.8/site-packages/***/utils/email.py:154: RemovedInAirflow3Warning: Fetching SMTP credentials from configuration variables will be deprecated in a future release. Please set credentials using a connection instead.
  send_mime_email(e_from=mail_from, e_to=recipients, mime_msg=msg, conn_id=conn_id, dryrun=dryrun)

[2024-09-03T14:46:24.954+0000] {configuration.py:1063} WARNING - section/key [smtp/smtp_user] not found in config
[2024-09-03T14:46:24.955+0000] {email.py:270} INFO - Email alerting: attempt 1
[2024-09-03T14:46:24.965+0000] {taskinstance.py:1935} ERROR - Task failed with exception
Traceback (most recent call last):
  File "/home/airflow/.local/lib/python3.8/site-packages/airflow/operators/email.py", line 77, in execute
    send_email(
  File "/home/airflow/.local/lib/python3.8/site-packages/airflow/utils/email.py", line 80, in send_email
    return backend(
  File "/home/airflow/.local/lib/python3.8/site-packages/airflow/utils/email.py", line 154, in send_email_smtp
    send_mime_email(e_from=mail_from, e_to=recipients, mime_msg=msg, conn_id=conn_id, dryrun=dryrun)
  File "/home/airflow/.local/lib/python3.8/site-packages/airflow/utils/email.py", line 272, in send_mime_email
    smtp_conn = _get_smtp_connection(smtp_host, smtp_port, smtp_timeout, smtp_ssl)
  File "/home/airflow/.local/lib/python3.8/site-packages/airflow/utils/email.py", line 317, in _get_smtp_connection
    return smtplib.SMTP(host=host, port=port, timeout=timeout)
  File "/usr/local/lib/python3.8/smtplib.py", line 255, in __init__
    (code, msg) = self.connect(host, port)
  File "/usr/local/lib/python3.8/smtplib.py", line 339, in connect
    self.sock = self._get_socket(host, port, self.timeout)
  File "/usr/local/lib/python3.8/smtplib.py", line 310, in _get_socket
    return socket.create_connection((host, port), timeout,
  File "/usr/local/lib/python3.8/socket.py", line 808, in create_connection
    raise err
  File "/usr/local/lib/python3.8/socket.py", line 796, in create_connection
    sock.connect(sa)
ConnectionRefusedError: [Errno 111] Connection refused
[2024-09-03T14:46:24.981+0000] {taskinstance.py:1398} INFO - Marking task as UP_FOR_RETRY. dag_id=k9_etl_dag_v7, task_id=send_report_email, execution_date=20240902T000000, start_date=20240903T144624, end_date=20240903T144624
[2024-09-03T14:46:24.991+0000] {standard_task_runner.py:104} ERROR - Failed to execute job 126 for task send_report_email ([Errno 111] Connection refused; 2913)
[2024-09-03T14:46:25.014+0000] {local_task_job_runner.py:228} INFO - Task exited with return code 1
[2024-09-03T14:46:25.044+0000] {taskinstance.py:2776} INFO - 0 downstream tasks scheduled from follow-on schedule check
