[2024-09-01T12:06:32.148+0000] {taskinstance.py:1157} INFO - Dependencies all met for dep_context=non-requeueable deps ti=<TaskInstance: k9_etl_dag.transform manual__2024-09-01T12:06:27.244089+00:00 [queued]>
[2024-09-01T12:06:32.152+0000] {taskinstance.py:1157} INFO - Dependencies all met for dep_context=requeueable deps ti=<TaskInstance: k9_etl_dag.transform manual__2024-09-01T12:06:27.244089+00:00 [queued]>
[2024-09-01T12:06:32.152+0000] {taskinstance.py:1359} INFO - Starting attempt 1 of 1
[2024-09-01T12:06:32.158+0000] {taskinstance.py:1380} INFO - Executing <Task(_PythonDecoratedOperator): transform> on 2024-09-01 12:06:27.244089+00:00
[2024-09-01T12:06:32.161+0000] {standard_task_runner.py:57} INFO - Started process 96 to run task
[2024-09-01T12:06:32.163+0000] {standard_task_runner.py:84} INFO - Running: ['***', 'tasks', 'run', 'k9_etl_dag', 'transform', 'manual__2024-09-01T12:06:27.244089+00:00', '--job-id', '18', '--raw', '--subdir', 'DAGS_FOLDER/k9_etl_dag.py', '--cfg-path', '/tmp/tmp1u4sv45b']
[2024-09-01T12:06:32.164+0000] {standard_task_runner.py:85} INFO - Job 18: Subtask transform
[2024-09-01T12:06:32.228+0000] {task_command.py:415} INFO - Running <TaskInstance: k9_etl_dag.transform manual__2024-09-01T12:06:27.244089+00:00 [running]> on host 3d54a521f848
[2024-09-01T12:06:32.280+0000] {taskinstance.py:1660} INFO - Exporting env vars: AIRFLOW_CTX_DAG_OWNER='***' AIRFLOW_CTX_DAG_ID='k9_etl_dag' AIRFLOW_CTX_TASK_ID='transform' AIRFLOW_CTX_EXECUTION_DATE='2024-09-01T12:06:27.244089+00:00' AIRFLOW_CTX_TRY_NUMBER='1' AIRFLOW_CTX_DAG_RUN_ID='manual__2024-09-01T12:06:27.244089+00:00'
[2024-09-01T12:06:32.281+0000] {taskinstance.py:1935} ERROR - Task failed with exception
Traceback (most recent call last):
  File "/home/airflow/.local/lib/python3.8/site-packages/airflow/decorators/base.py", line 221, in execute
    return_value = super().execute(context)
  File "/home/airflow/.local/lib/python3.8/site-packages/airflow/operators/python.py", line 192, in execute
    return_value = self.execute_callable()
  File "/home/airflow/.local/lib/python3.8/site-packages/airflow/operators/python.py", line 209, in execute_callable
    return self.python_callable(*self.op_args, **self.op_kwargs)
  File "/opt/airflow/dags/k9_etl_dag.py", line 29, in transform
    for item in data.get("dogs", []):
AttributeError: 'list' object has no attribute 'get'
[2024-09-01T12:06:32.287+0000] {taskinstance.py:1398} INFO - Marking task as FAILED. dag_id=k9_etl_dag, task_id=transform, execution_date=20240901T120627, start_date=20240901T120632, end_date=20240901T120632
[2024-09-01T12:06:32.293+0000] {standard_task_runner.py:104} ERROR - Failed to execute job 18 for task transform ('list' object has no attribute 'get'; 96)
[2024-09-01T12:06:32.322+0000] {local_task_job_runner.py:228} INFO - Task exited with return code 1
[2024-09-01T12:06:32.336+0000] {taskinstance.py:2776} INFO - 0 downstream tasks scheduled from follow-on schedule check
