[2024-09-02T19:14:40.853+0000] {taskinstance.py:1157} INFO - Dependencies all met for dep_context=non-requeueable deps ti=<TaskInstance: k9_etl_dag.create_k9_table manual__2024-09-02T19:14:39.787843+00:00 [queued]>
[2024-09-02T19:14:40.860+0000] {taskinstance.py:1157} INFO - Dependencies all met for dep_context=requeueable deps ti=<TaskInstance: k9_etl_dag.create_k9_table manual__2024-09-02T19:14:39.787843+00:00 [queued]>
[2024-09-02T19:14:40.860+0000] {taskinstance.py:1359} INFO - Starting attempt 1 of 1
[2024-09-02T19:14:40.872+0000] {taskinstance.py:1380} INFO - Executing <Task(SQLExecuteQueryOperator): create_k9_table> on 2024-09-02 19:14:39.787843+00:00
[2024-09-02T19:14:40.899+0000] {standard_task_runner.py:57} INFO - Started process 308 to run task
[2024-09-02T19:14:40.906+0000] {standard_task_runner.py:84} INFO - Running: ['***', 'tasks', 'run', 'k9_etl_dag', 'create_k9_table', 'manual__2024-09-02T19:14:39.787843+00:00', '--job-id', '18', '--raw', '--subdir', 'DAGS_FOLDER/k9_etl_dag.py', '--cfg-path', '/tmp/tmpnabbvrr1']
[2024-09-02T19:14:40.908+0000] {standard_task_runner.py:85} INFO - Job 18: Subtask create_k9_table
[2024-09-02T19:14:40.965+0000] {task_command.py:415} INFO - Running <TaskInstance: k9_etl_dag.create_k9_table manual__2024-09-02T19:14:39.787843+00:00 [running]> on host 6b66813f7393
[2024-09-02T19:14:41.018+0000] {taskinstance.py:1660} INFO - Exporting env vars: AIRFLOW_CTX_DAG_OWNER='***' AIRFLOW_CTX_DAG_ID='k9_etl_dag' AIRFLOW_CTX_TASK_ID='create_k9_table' AIRFLOW_CTX_EXECUTION_DATE='2024-09-02T19:14:39.787843+00:00' AIRFLOW_CTX_TRY_NUMBER='1' AIRFLOW_CTX_DAG_RUN_ID='manual__2024-09-02T19:14:39.787843+00:00'
[2024-09-02T19:14:41.019+0000] {sql.py:274} INFO - Executing: 
        CREATE TABLE IF NOT EXISTS k9_facts (
            id SERIAL PRIMARY KEY,
            created_date TIMESTAMP,
            description TEXT
        );
        
[2024-09-02T19:14:41.025+0000] {base.py:73} INFO - Using connection ID 'k9_care' for task execution.
[2024-09-02T19:14:41.040+0000] {base.py:73} INFO - Using connection ID 'k9_care' for task execution.
[2024-09-02T19:14:41.043+0000] {taskinstance.py:1935} ERROR - Task failed with exception
Traceback (most recent call last):
  File "/home/airflow/.local/lib/python3.8/site-packages/airflow/providers/common/sql/operators/sql.py", line 280, in execute
    output = hook.run(
  File "/home/airflow/.local/lib/python3.8/site-packages/airflow/providers/common/sql/hooks/sql.py", line 385, in run
    with closing(self.get_conn()) as conn:
  File "/home/airflow/.local/lib/python3.8/site-packages/airflow/providers/postgres/hooks/postgres.py", line 154, in get_conn
    self.conn = psycopg2.connect(**conn_args)
  File "/home/airflow/.local/lib/python3.8/site-packages/psycopg2/__init__.py", line 122, in connect
    conn = _connect(dsn, connection_factory=connection_factory, **kwasync)
psycopg2.OperationalError: connection to server at "127.0.0.1", port 5432 failed: Connection refused
	Is the server running on that host and accepting TCP/IP connections?

[2024-09-02T19:14:41.058+0000] {taskinstance.py:1398} INFO - Marking task as FAILED. dag_id=k9_etl_dag, task_id=create_k9_table, execution_date=20240902T191439, start_date=20240902T191440, end_date=20240902T191441
[2024-09-02T19:14:41.065+0000] {standard_task_runner.py:104} ERROR - Failed to execute job 18 for task create_k9_table (connection to server at "127.0.0.1", port 5432 failed: Connection refused
	Is the server running on that host and accepting TCP/IP connections?
; 308)
[2024-09-02T19:14:41.088+0000] {local_task_job_runner.py:228} INFO - Task exited with return code 1
[2024-09-02T19:14:41.108+0000] {taskinstance.py:2776} INFO - 0 downstream tasks scheduled from follow-on schedule check
